<?xml version="1.0"?>
<robot xmlns:xacro="http://www.ros.org/wiki/xacro" name="dummy_bot">
    <link name="base_link">
        <visual>
            <origin xyz="0 0 0.06" />
            <geometry>
                <box size="0.3 0.2 0.1" />
            </geometry>
        </visual>
        <collision>
            <geometry>
                <box size="0.3 0.2 0.1" />
            </geometry>
        </collision>
        <inertial>
            <mass value="5.0" />
            <inertia ixx="1.0" ixy="0.0" ixz="0.0" iyy="1.0" iyz="0.0" izz="1.0" />
        </inertial>
    </link>
    <link name="left_wheel_link">
        <visual>
            <origin rpy="1.5707 0 0" />
            <geometry>
                <cylinder radius="0.05" length="0.04" />
            </geometry>
        </visual>
        <collision>
            <origin rpy="1.5707 0 0" />
            <geometry>
                <cylinder radius="0.05" length="0.04" />
            </geometry>
        </collision>
        <inertial>
            <mass value="0.5" />
            <inertia ixx="1.0" ixy="0.0" ixz="0.0" iyy="1.0" iyz="0.0" izz="1.0" />
        </inertial>
    </link>
    <link name="right_wheel_link">
        <visual>
            <origin rpy="1.5707 0 0" />
            <geometry>
                <cylinder radius="0.05" length="0.04" />
            </geometry>
        </visual>
        <collision>
            <origin rpy="1.5707 0 0" />
            <geometry>
                <cylinder radius="0.05" length="0.04" />
            </geometry>
        </collision>
        <inertial>
            <mass value="0.5" />
            <inertia ixx="1.0" ixy="0.0" ixz="0.0" iyy="1.0" iyz="0.0" izz="1.0" />
        </inertial>
    </link>
    <joint name="left_wheel_joint" type="continuous">
        <parent link="base_link" />
        <child link="left_wheel_link" />
        <origin xyz="0 0.12 0.04" />
        <axis xyz="0 1 0" />
    </joint>
    <joint name="right_wheel_joint" type="continuous">
        <parent link="base_link" />
        <child link="right_wheel_link" />
        <origin xyz="0 -0.12 0.04" />
        <axis xyz="0 1 0" />
    </joint>
    <plugin
        filename="gz-sim-diff-drive-system"
        name="gz::sim::systems::DiffDrive">
        <left_joint>left_wheel_joint</left_joint>
        <right_joint>right_wheel_joint</right_joint>
        <frame_id>odom</frame_id>
        <child_frame_id>base_link</child_frame_id>
        <wheel_separation>0.24</wheel_separation>
        <wheel_radius>0.05</wheel_radius>
    </plugin>
    <plugin
        filename="gz-sim-joint-state-publisher-system"
        name="gz::sim::systems::JointStatePublisher">
    </plugin>

</robot>